[TMainForm.FCTest] =======================================================
C:\Python\Python312\Lib\site-packages\keras\src\layers\core\dense.py:87: UserWarning: Do not pass an `input_shape`/`input_dim` argument to a layer. When using Sequential models, prefer using an `Input(shape)` object as the first layer in the model instead.
  super().__init__(activity_regularizer=activity_regularizer, **kwargs)
=======================================================
---- X:\Projects\KR\Test\NeuralNetwork\nn\tests\py\fc.py
epsilon= 1e-10
Traceback (most recent call last):
  File "X:\Projects\KR\Test\NeuralNetwork\nn\tests\py\fc.py", line 81, in <module>
    y_data = model(x_data)
             ^^^^^^^^^^^^^
  File "C:\Python\Python312\Lib\site-packages\keras\src\utils\traceback_utils.py", line 122, in error_handler
    raise e.with_traceback(filtered_tb) from None
  File "C:\Python\Python312\Lib\site-packages\keras\src\models\functional.py", line 272, in _adjust_input_rank
    raise ValueError(
ValueError: Exception encountered when calling Sequential.call().

[1mInvalid input shape for input [0. 0. 0. 0. 0.]. Expected shape (None, 5), but input has incompatible shape (5,)[0m

Arguments received by Sequential.call():
  • inputs=tf.Tensor(shape=(5,), dtype=float64)
  • training=None
  • mask=None

[TMainForm.FCTest] ERROR: not FileExists('X:\Projects\KR\Test\NeuralNetwork\nn\tests\data\20250818\FC_Forward104910\ydata.dat')
[TMainForm.FCTest] =======================================================
C:\Python\Python312\Lib\site-packages\keras\src\layers\core\dense.py:87: UserWarning: Do not pass an `input_shape`/`input_dim` argument to a layer. When using Sequential models, prefer using an `Input(shape)` object as the first layer in the model instead.
  super().__init__(activity_regularizer=activity_regularizer, **kwargs)
=======================================================
---- X:\Projects\KR\Test\NeuralNetwork\nn\tests\py\fc.py
epsilon= 1e-10
Traceback (most recent call last):
  File "X:\Projects\KR\Test\NeuralNetwork\nn\tests\py\fc.py", line 83, in <module>
    y_data = model(x_data)
             ^^^^^^^^^^^^^
  File "C:\Python\Python312\Lib\site-packages\keras\src\utils\traceback_utils.py", line 122, in error_handler
    raise e.with_traceback(filtered_tb) from None
  File "C:\Python\Python312\Lib\site-packages\keras\src\models\functional.py", line 272, in _adjust_input_rank
    raise ValueError(
ValueError: Exception encountered when calling Sequential.call().

[1mInvalid input shape for input [0. 0. 0. 0. 0.]. Expected shape (None, 5), but input has incompatible shape (5,)[0m

Arguments received by Sequential.call():
  • inputs=tf.Tensor(shape=(5,), dtype=float64)
  • training=None
  • mask=None

[TMainForm.FCTest] ERROR: not FileExists('X:\Projects\KR\Test\NeuralNetwork\nn\tests\data\20250818\FC_Forward105135\ydata.dat')
[TMainForm.FCTest] =======================================================
C:\Python\Python312\Lib\site-packages\keras\src\layers\core\dense.py:87: UserWarning: Do not pass an `input_shape`/`input_dim` argument to a layer. When using Sequential models, prefer using an `Input(shape)` object as the first layer in the model instead.
  super().__init__(activity_regularizer=activity_regularizer, **kwargs)
=======================================================
---- X:\Projects\KR\Test\NeuralNetwork\nn\tests\py\fc.py
epsilon= 1e-10
ydata: [[0.]]

[TMainForm.FCTest] ERROR: not LoadFloatArrayFromFile('X:\Projects\KR\Test\NeuralNetwork\nn\tests\data\20250818\FC_Forward105446\ydata.dat')
